<?xml version="1.0"?>
<robot name="robot_arm">


    <material name="blue">
        <color rgba="0.0 0.0 0.8 1.0"/>
    </material>
    
    <material name="abb_orange">
        <color rgba="1.0 0.43 0 1.0"/>
    </material>

    <material name="gray_dark">
        <color rgba="0.7 0.7 0.7 1.0"/>
    </material>
    
    <link name="world"/>
    
    <link name="base_link">
        <visual>
            <geometry>
                <mesh filename="package://abb_1600ws/meshes/visual/base_link.stl"/>
            </geometry>
            <origin xyz="0.0 0.0 0.0" rpy="0.0 0.0 0.0"/>
            <material name="abb_orange"/>
            
        </visual>
        <collision>
            <geometry>
                <mesh filename="package://abb_1600ws/meshes/collision/base_link.stl"/>
            </geometry>
             
        </collision>
        <inertial>
            <mass value="10"/>
            <inertia ixx="0.4" ixy="0.0" ixz="0.0" iyy="0.4" iyz="0.0" izz="0.2"/>
        </inertial>

    </link>
    
    <link name="link_1_rev">
        <visual>
            <geometry>
                <mesh filename="package://abb_1600ws/meshes/visual/link_1.stl"/>
            </geometry>
            <origin xyz="0.0 0.0 0.0" rpy="0.0 0.0 0.0"/>
            <material name="abb_orange"/>
            
        </visual>
        <collision>
            <geometry>
                <mesh filename="package://abb_1600ws/meshes/collision/link_1.stl"/>
            </geometry>
        </collision>
    </link>
    
    <link name="link_1_DH">
        <inertial>
            <mass value="1"/>
            <!--inertia ixx="0.4" ixy="0.0" ixz="0.0" iyy="0.4" iyz="0.0" izz="0.2"/-->
            <inertia ixx="0.0" ixy="0.0" ixz="0.0" iyy="0.0" iyz="0.0" izz="0.0"/>
        </inertial>
    </link>
    
    <link name="link_2_rev">
        <visual>
            <geometry>
                <mesh filename="package://abb_1600ws/meshes/visual/link_2.stl"/>
            </geometry>
            <origin xyz="0 0 0" rpy="1.570795 0.0 0.0"/>
            <material name="abb_orange"/>
            
        </visual>
        <collision>
            <geometry>
                <mesh filename="package://abb_1600ws/meshes/collision/link_2.stl"/>
            </geometry>
        </collision>
    </link>
    
    <link name="link_2_DH">
        <inertial>
            <mass value="1"/>
            <!--inertia ixx="0.4" ixy="0.0" ixz="0.0" iyy="0.4" iyz="0.0" izz="0.2"/-->
            <inertia ixx="0.0" ixy="0.0" ixz="0.0" iyy="0.0" iyz="0.0" izz="0.0"/>
        </inertial>
    </link>

    <link name="link_3_rev">
        <visual>
            <geometry>
                <mesh filename="package://abb_1600ws/meshes/visual/link_3.stl"/>
            </geometry>
            <origin xyz="0 0 0" rpy="1.570795 0.0 0.0"/>
            <material name="abb_orange"/>
            
        </visual>
        <collision>
            <geometry>
                <mesh filename="package://abb_1600ws/meshes/collision/link_3.stl"/>
            </geometry>
        </collision>
    </link>

    <link name="link_3_DH">
        <inertial>
            <mass value="1"/>
            <!--inertia ixx="0.4" ixy="0.0" ixz="0.0" iyy="0.4" iyz="0.0" izz="0.2"/-->
            <inertia ixx="0.0" ixy="0.0" ixz="0.0" iyy="0.0" iyz="0.0" izz="0.0"/>
        </inertial>
    </link>

    <link name="link_4_rev">
        <visual>
            <geometry>
                <mesh filename="package://abb_1600ws/meshes/visual/link_4.stl"/>
            </geometry>
            <origin xyz="0 0 0" rpy="0.0 -1.570795 0.0"/>
            <material name="abb_orange"/>
            
        </visual>
        <collision>
            <geometry>
                <mesh filename="package://abb_1600ws/meshes/collision/link_4.stl"/>
            </geometry>
        </collision>
    </link>

    <link name="link_4_DH">
        <inertial>
            <mass value="1"/>
            <!--inertia ixx="0.4" ixy="0.0" ixz="0.0" iyy="0.4" iyz="0.0" izz="0.2"/-->
            <inertia ixx="0.0" ixy="0.0" ixz="0.0" iyy="0.0" iyz="0.0" izz="0.0"/>
        </inertial>
    </link>

    <link name="link_5_rev">
        <visual>
            <geometry>
                <mesh filename="package://abb_1600ws/meshes/visual/link_5.stl"/>
            </geometry>
            <origin xyz="0 0 0" rpy="0.0 0.0 0.0"/>
            <material name="abb_orange"/>
            
        </visual>
        <collision>
            <geometry>
                <mesh filename="package://abb_1600ws/meshes/collision/link_5.stl"/>
            </geometry>
        </collision>
    </link>

    <link name="link_5_DH">
        <inertial>
            <mass value="1"/>
            <!--inertia ixx="0.4" ixy="0.0" ixz="0.0" iyy="0.4" iyz="0.0" izz="0.2"/-->
            <inertia ixx="0.0" ixy="0.0" ixz="0.0" iyy="0.0" iyz="0.0" izz="0.0"/>
        </inertial>
    </link>

    <link name="link_6_rev">
        <visual>
            <geometry>
                <mesh filename="package://abb_1600ws/meshes/visual/link_6.stl"/>
            </geometry>
            <origin xyz="0 0 0.065" rpy="0.0 -1.570795 0.0"/>
            <material name="abb_orange"/>
            
        </visual>
        <collision>
            <geometry>
                <mesh filename="package://abb_1600ws/meshes/collision/link_6.stl"/>
            </geometry>
        </collision>
    </link>

    <link name="link_6_DH">
        <inertial>
            <mass value="1"/>
            <!--inertia ixx="0.4" ixy="0.0" ixz="0.0" iyy="0.4" iyz="0.0" izz="0.2"/-->
            <inertia ixx="0.0" ixy="0.0" ixz="0.0" iyy="0.0" iyz="0.0" izz="0.0"/>
        </inertial>
    </link>
    
    <joint name="fixed" type="fixed">
        <parent link="world" />
        <child link="base_link" />
    </joint>
    
    <joint name="jnt1_rev" type="revolute">
        <parent link="base_link"/>
        <child link="link_1_rev"/>
        <axis xyz="0 0 1"/>
        <limit lower="-3.14159" upper="3.14159" velocity="500.0" effort="1000.0"/>
        <origin xyz="0 0 0" rpy="0 0 0"/>
    </joint>
    
    <joint name="jnt1_DH" type="fixed">
        <parent link="link_1_rev"/>
        <child link="link_1_DH"/>
        <origin xyz="0.15 0 0.4865" rpy="-1.570795 0 0"/>
    </joint>

    <joint name="jnt2_rev" type="revolute">
        <parent link="link_1_DH"/>
        <child link="link_2_rev"/>
        <axis xyz="0 0 1"/>
        <limit lower="-1.09955" upper="1.91986" velocity="500.0" effort="1000.0"/>
        <origin xyz="0 0 0" rpy="0 0 0"/>
    </joint>
    
    <joint name="jnt2_DH" type="fixed">
        <parent link="link_2_rev"/>
        <child link="link_2_DH"/>
        <origin xyz="0 -0.475 0" rpy="0 0 0"/>
    </joint>

    <joint name="jnt3_rev" type="revolute">
        <parent link="link_2_DH"/>
        <child link="link_3_rev"/>
        <axis xyz="0 0 1"/>
        <limit lower="-4.10152" upper="0.95993" velocity="500.0" effort="1000.0"/>
        <origin xyz="0 0 0" rpy="0 0 0"/>
    </joint>
    
    <joint name="jnt3_DH" type="fixed">
        <parent link="link_3_rev"/>
        <child link="link_3_DH"/>
        <origin xyz="0.3 0 0" rpy="-1.570795 0 -1.570795"/>
    </joint>
    
    <joint name="jnt4_rev" type="revolute">
        <parent link="link_3_DH"/>
        <child link="link_4_rev"/>
        <axis xyz="0 0 1"/>
        <limit lower="-3.49065" upper="3.49065" velocity="500.0" effort="1000.0"/>
        <origin xyz="0 0 0" rpy="0 0 0"/>
    </joint>

    <joint name="jnt4_DH" type="fixed">
        <parent link="link_4_rev"/>
        <child link="link_4_DH"/>
        <origin xyz="0 0 0.3" rpy="1.570795 0 0"/>
    </joint>

    <joint name="jnt5_rev" type="revolute">
        <parent link="link_4_DH"/>
        <child link="link_5_rev"/>
        <axis xyz="0 0 1"/>
        <limit lower="-2.00712" upper="2.00712" velocity="500.0" effort="1000.0"/>
        <origin xyz="0 0 0" rpy="0 0 0"/>
    </joint>

    <joint name="jnt5_DH" type="fixed">
        <parent link="link_5_rev"/>
        <child link="link_5_DH"/>
        <origin xyz="0 0 0" rpy="-1.570795 0 -1.570795"/>
    </joint>

    <joint name="jnt6_rev" type="revolute">
        <parent link="link_5_DH"/>
        <child link="link_6_rev"/>
        <axis xyz="0 0 1"/>
        <limit lower="-6.98131" upper="6.98131" velocity="500.0" effort="1000.0"/>
        <origin xyz="0 0 0" rpy="0 0 0"/>
    </joint>

    <joint name="jnt6_DH" type="fixed">
        <parent link="link_6_rev"/>
        <child link="link_6_DH"/>
        <origin xyz="0 0 0.065" rpy="0 0 0"/>
    </joint>
    
</robot>
    
    
    
    
    
    
    
    
